Workbook
Name Slicer_Gender: #N/A
Name Slicer_ParentalSupport: #N/A

Sheet Student_performance_data _
A1: StudentID | B1: Age | C1: Gender | D1: Ethnicity | E1: ParentalEducation | F1: StudyTimeWeekly | G1: Absences | H1: Tutoring | I1: ParentalSupport | J1: Extracurricular | K1: Sports | L1: Music | M1: Volunteering | N1: GPA | O1: GradeClass
A2: 1001 | B2: 17 | C2: 1 | D2: 0 | E2: 2 | F2: 19.833722807854713 | G2: 7 | H2: 1 | I2: 2 | J2: 0 | K2: 0 | L2: 1 | M2: 0 | N2: 2.929195591667681 | O2: 2
A3: 1002 | B3: 18 | C3: 0 | D3: 0 | E3: 1 | F3: 15.40875605584674 | G3: 0 | H3: 0 | I3: 1 | J3: 0 | K3: 0 | L3: 0 | M3: 0 | N3: 3.042914833436377 | O3: 1
A4: 1003 | B4: 15 | C4: 0 | D4: 2 | E4: 3 | F4: 4.2105698 | G4: 26 | H4: 0 | I4: 2 | J4: 0 | K4: 0 | L4: 0 | M4: 0 | N4: 0.1126022544661815 | O4: 4
A5: 1004 | B5: 17 | C5: 1 | D5: 0 | E5: 3 | F5: 10.028829473958215 | G5: 14 | H5: 0 | I5: 3 | J5: 1 | K5: 0 | L5: 0 | M5: 0 | N5: 2.0542181397029484 | O5: 3
A6: 1005 | B6: 17 | C6: 1 | D6: 0 | E6: 2 | F6: 4.6724952729713305 | G6: 17 | H6: 1 | I6: 3 | J6: 0 | K6: 0 | L6: 0 | M6: 0 | N6: 1.2880611817953875 | O6: 4
A7: 1006 | B7: 18 | C7: 0 | D7: 0 | E7: 1 | F7: 8.191218545250186 | G7: 0 | H7: 0 | I7: 1 | J7: 1 | K7: 0 | L7: 0 | M7: 0 | N7: 3.0841836144863937 | O7: 1
A8: 1007 | B8: 15 | C8: 0 | D8: 1 | E8: 1 | F8: 15.601680474699295 | G8: 10 | H8: 0 | I8: 3 | J8: 0 | K8: 1 | L8: 0 | M8: 0 | N8: 2.748237414891583 | O8: 2
A9: 1008 | B9: 15 | C9: 1 | D9: 1 | E9: 4 | F9: 15.424496305808074 | G9: 22 | H9: 1 | I9: 1 | J9: 1 | K9: 0 | L9: 0 | M9: 0 | N9: 1.360142712316461 | O9: 4
A10: 1009 | B10: 17 | C10: 0 | D10: 0 | E10: 0 | F10: 4.562007558047703 | G10: 1 | H10: 0 | I10: 2 | J10: 0 | K10: 1 | L10: 0 | M10: 1 | N10: 2.896819189513569 | O10: 2
A11: 1010 | B11: 16 | C11: 1 | D11: 0 | E11: 1 | F11: 18.444466363097202 | G11: 0 | H11: 0 | I11: 3 | J11: 1 | K11: 0 | L11: 0 | M11: 0 | N11: 3.5734742103297656 | O11: 0
A12: 1011 | B12: 17 | C12: 0 | D12: 0 | E12: 1 | F12: 11.851363655296536 | G12: 11 | H12: 0 | I12: 1 | J12: 0 | K12: 0 | L12: 0 | M12: 0 | N12: 2.1471716250185144 | O12: 3
A13: 1012 | B13: 17 | C13: 0 | D13: 0 | E13: 1 | F13: 7.5984858 | G13: 15 | H13: 0 | I13: 2 | J13: 0 | K13: 0 | L13: 0 | M13: 1 | N13: 1.5595945190402773 | O13: 4
A14: 1013 | B14: 17 | C14: 0 | D14: 1 | E14: 1 | F14: 10.038711615617213 | G14: 21 | H14: 0 | I14: 3 | J14: 1 | K14: 0 | L14: 0 | M14: 0 | N14: 1.520077814874808 | O14: 4
A15: 1014 | B15: 17 | C15: 0 | D15: 1 | E15: 2 | F15: 12.101425068754875 | G15: 21 | H15: 0 | I15: 4 | J15: 0 | K15: 1 | L15: 0 | M15: 0 | N15: 1.7515809583340785 | O15: 4
A16: 1015 | B16: 18 | C16: 1 | D16: 0 | E16: 1 | F16: 11.197810636915708 | G16: 9 | H16: 1 | I16: 2 | J16: 0 | K16: 0 | L16: 0 | M16: 0 | N16: 2.396788117124796 | O16: 3
A17: 1016 | B17: 15 | C17: 0 | D17: 0 | E17: 2 | F17: 9.728100710723563 | G17: 17 | H17: 1 | I17: 0 | J17: 0 | K17: 1 | L17: 0 | M17: 0 | N17: 1.3415207165346672 | O17: 4
A18: 1017 | B18: 18 | C18: 0 | D18: 3 | E18: 1 | F18: 10.098656081788002 | G18: 14 | H18: 0 | I18: 2 | J18: 1 | K18: 1 | L18: 0 | M18: 0 | N18: 2.2321752777159762 | O18: 3
A19: 1018 | B19: 18 | C19: 1 | D19: 0 | E19: 0 | F19: 3.5282382085577235 | G19: 16 | H19: 1 | I19: 2 | J19: 0 | K19: 0 | L19: 0 | M19: 0 | N19: 1.3844041756940335 | O19: 4
A20: 1019 | B20: 18 | C20: 0 | D20: 1 | E20: 3 | F20: 16.25465808609359 | G20: 29 | H20: 0 | I20: 2 | J20: 1 | K20: 0 | L20: 0 | M20: 1 | N20: 0.4695533233798704 | O20: 4
A21: 1020 | B21: 17 | C21: 0 | D21: 0 | E21: 1 | F21: 10.835206398820308 | G21: 9 | H21: 0 | I21: 2 | J21: 0 | K21: 0 | L21: 1 | M21: 0 | N21: 2.3957840945306996 | O21: 3
A22: 1021 | B22: 16 | C22: 1 | D22: 0 | E22: 3 | F22: 2.621597234094062 | G22: 2 | H22: 0 | I22: 3 | J22: 0 | K22: 0 | L22: 0 | M22: 1 | N22: 2.778411299920653 | O22: 2
A23: 1022 | B23: 15 | C23: 0 | D23: 0 | E23: 2 | F23: 15.323142031655559 | G23: 25 | H23: 0 | I23: 1 | J23: 1 | K23: 0 | L23: 0 | M23: 0 | N23: 0.34689403670501484 | O23: 4
A24: 1023 | B24: 16 | C24: 1 | D24: 1 | E24: 0 | F24: 18.648879567547016 | G24: 29 | H24: 1 | I24: 1 | J24: 0 | K24: 0 | L24: 0 | M24: 0 | N24: 0.3125462305253549 | O24: 4
A25: 1024 | B25: 18 | C25: 1 | D25: 3 | E25: 4 | F25: 18.94613798473924 | G25: 20 | H25: 0 | I25: 2 | J25: 1 | K25: 0 | L25: 0 | M25: 0 | N25: 1.7701318767799732 | O25: 4
... A30: 1029 | B30: 18 | C30: 0 | D30: 0 | E30: 0 | F30: 18.679748370252344 | G30: 10 | H30: 0 | I30: 3 | J30: 1 | K30: 0 | L30: 0 | M30: 0 | N30: 2.854803928981318 | O30: 2
A31: 1030 | B31: 18 | C31: 0 | D31: 0 | E31: 2 | F31: 3.6715925 | G31: 20 | H31: 0 | I31: 3 | J31: 1 | K31: 0 | L31: 0 | M31: 0 | N31: 1.519441725815139 | O31: 4
A32: 1031 | B32: 15 | C32: 0 | D32: 2 | E32: 2 | F32: 5.055317199023282 | G32: 12 | H32: 1 | I32: 0 | J32: 0 | K32: 1 | L32: 0 | M32: 0 | N32: 1.727120309522409 | O32: 4
A33: 1032 | B33: 15 | C33: 0 | D33: 0 | E33: 3 | F33: 8.132730537699409 | G33: 17 | H33: 0 | I33: 4 | J33: 0 | K33: 0 | L33: 0 | M33: 1 | N33: 1.8475354711387906 | O33: 4
A34: 1033 | B34: 18 | C34: 0 | D34: 0 | E34: 3 | F34: 7.663289371182516 | G34: 25 | H34: 0 | I34: 1 | J34: 0 | K34: 1 | L34: 0 | M34: 0 | N34: 0.38461697285648777 | O34: 4
A35: 1034 | B35: 16 | C35: 0 | D35: 3 | E35: 3 | F35: 15.89325784795778 | G35: 21 | H35: 0 | I35: 0 | J35: 1 | K35: 1 | L35: 0 | M35: 0 | N35: 0.9494061 | O35: 4
A36: 1035 | B36: 16 | C36: 0 | D36: 0 | E36: 3 | F36: 9.126336411019247 | G36: 27 | H36: 1 | I36: 2 | J36: 1 | K36: 1 | L36: 0 | M36: 0 | N36: 1.1409594184203395 | O36: 4
A37: 1036 | B37: 15 | C37: 0 | D37: 3 | E37: 1 | F37: 3.415365200066738 | G37: 23 | H37: 0 | I37: 1 | J37: 0 | K37: 0 | L37: 0 | M37: 0 | N37: 0.2614722600507521 | O37: 4
A38: 1037 | B38: 18 | C38: 0 | D38: 0 | E38: 1 | F38: 5.344197909721482 | G38: 26 | H38: 1 | I38: 1 | J38: 0 | K38: 0 | L38: 0 | M38: 0 | N38: 0.21828485682103177 | O38: 4
A39: 1038 | B39: 15 | C39: 0 | D39: 2 | E39: 1 | F39: 10.18226770375044 | G39: 21 | H39: 1 | I39: 1 | J39: 0 | K39: 1 | L39: 0 | M39: 0 | N39: 1.0677635510419796 | O39: 4
A40: 1039 | B40: 15 | C40: 1 | D40: 1 | E40: 1 | F40: 2.949078348522698 | G40: 3 | H40: 1 | I40: 1 | J40: 1 | K40: 1 | L40: 0 | M40: 0 | N40: 3.0189058584279675 | O40: 1
A41: 1040 | B41: 17 | C41: 1 | D41: 2 | E41: 1 | F41: 12.233113512920282 | G41: 21 | H41: 1 | I41: 3 | J41: 1 | K41: 1 | L41: 0 | M41: 0 | N41: 1.5268678317927231 | O41: 4
A42: 1041 | B42: 17 | C42: 1 | D42: 3 | E42: 2 | F42: 11.314946131022918 | G42: 23 | H42: 1 | I42: 1 | J42: 0 | K42: 0 | L42: 0 | M42: 0 | N42: 1.0582873996898603 | O42: 4
A43: 1042 | B43: 17 | C43: 0 | D43: 0 | E43: 1 | F43: 14.294046327645153 | G43: 7 | H43: 0 | I43: 2 | J43: 0 | K43: 0 | L43: 0 | M43: 0 | N43: 2.625128097732231 | O43: 2
A44: 1043 | B44: 16 | C44: 1 | D44: 3 | E44: 2 | F44: 18.754092307587353 | G44: 12 | H44: 1 | I44: 4 | J44: 0 | K44: 0 | L44: 0 | M44: 0 | N44: 2.8087548220286536 | O44: 2
...

Sheet Cleaned_Data
A1: StudentID | B1: Age | C1: Gender | D1: Ethnicity | E1: ParentalEducation | F1: StudyTimeWeekly(Hours) | G1: Absences | H1: Tutoring | I1: ParentalSupport | J1: Extracurricular | K1: Sports | L1: Music | M1: Volunteering | N1: GPA | O1: GradeClass | P1: Remark
A2: 1001 | B2: 17 | C2: Female | D2: General | E2: Post Graduation | F2: 20 | G2: 7 | H2: Yes | I2: Moderate support | J2: No | K2: No | L2: Yes | M2: No | N2: 3 | O2: 2 | P2: =IF(Cleaned_Data!$N2>=3.5,"Excellent",IF(Cleaned_Data!$N2>=3,"Good",IF(Cleaned_Data!$N2>=2,"Average",IF(Cleaned_Data!$N2>=1,"Below Average","Very Poor")))) -> Good
A3: 1002 | B3: 18 | C3: Male | D3: General | E3: Graduation | F3: 15 | G3: 0 | H3: No | I3: Low support | J3: No | K3: No | L3: No | M3: No | N3: 3 | O3: 1 | P3: =IF(Cleaned_Data!$N3>=3.5,"Excellent",IF(Cleaned_Data!$N3>=3,"Good",IF(Cleaned_Data!$N3>=2,"Average",IF(Cleaned_Data!$N3>=1,"Below Average","Very Poor")))) -> Good
A4: 1003 | B4: 15 | C4: Male | D4: SC | E4: Secondary | F4: 4 | G4: 26 | H4: No | I4: Moderate support | J4: No | K4: No | L4: No | M4: No | N4: 0 | O4: 4 | P4: =IF(Cleaned_Data!$N4>=3.5,"Excellent",IF(Cleaned_Data!$N4>=3,"Good",IF(Cleaned_Data!$N4>=2,"Average",IF(Cleaned_Data!$N4>=1,"Below Average","Very Poor")))) -> Very Poor
A5: 1004 | B5: 17 | C5: Female | D5: General | E5: Secondary | F5: 10 | G5: 14 | H5: No | I5: High support | J5: Yes | K5: No | L5: No | M5: No | N5: 2 | O5: 3 | P5: =IF(Cleaned_Data!$N5>=3.5,"Excellent",IF(Cleaned_Data!$N5>=3,"Good",IF(Cleaned_Data!$N5>=2,"Average",IF(Cleaned_Data!$N5>=1,"Below Average","Very Poor")))) -> Average
A6: 1005 | B6: 17 | C6: Female | D6: General | E6: Post Graduation | F6: 5 | G6: 17 | H6: Yes | I6: High support | J6: No | K6: No | L6: No | M6: No | N6: 1 | O6: 4 | P6: =IF(Cleaned_Data!$N6>=3.5,"Excellent",IF(Cleaned_Data!$N6>=3,"Good",IF(Cleaned_Data!$N6>=2,"Average",IF(Cleaned_Data!$N6>=1,"Below Average","Very Poor")))) -> Below Average
A7: 1006 | B7: 18 | C7: Male | D7: General | E7: Graduation | F7: 8 | G7: 0 | H7: No | I7: Low support | J7: Yes | K7: No | L7: No | M7: No | N7: 3 | O7: 1 | P7: =IF(Cleaned_Data!$N7>=3.5,"Excellent",IF(Cleaned_Data!$N7>=3,"Good",IF(Cleaned_Data!$N7>=2,"Average",IF(Cleaned_Data!$N7>=1,"Below Average","Very Poor")))) -> Good
A8: 1007 | B8: 15 | C8: Male | D8: ST | E8: Graduation | F8: 16 | G8: 10 | H8: No | I8: High support | J8: No | K8: Yes | L8: No | M8: No | N8: 3 | O8: 2 | P8: =IF(Cleaned_Data!$N8>=3.5,"Excellent",IF(Cleaned_Data!$N8>=3,"Good",IF(Cleaned_Data!$N8>=2,"Average",IF(Cleaned_Data!$N8>=1,"Below Average","Very Poor")))) -> Good
A9: 1008 | B9: 15 | C9: Female | D9: ST | E9: Higher Secondary | F9: 15 | G9: 22 | H9: Yes | I9: Low support | J9: Yes | K9: No | L9: No | M9: No | N9: 1 | O9: 4 | P9: =IF(Cleaned_Data!$N9>=3.5,"Excellent",IF(Cleaned_Data!$N9>=3,"Good",IF(Cleaned_Data!$N9>=2,"Average",IF(Cleaned_Data!$N9>=1,"Below Average","Very Poor")))) -> Below Average
A10: 1009 | B10: 17 | C10: Male | D10: General | E10: No Schooling | F10: 5 | G10: 1 | H10: No | I10: Moderate support | J10: No | K10: Yes | L10: No | M10: Yes | N10: 3 | O10: 2 | P10: =IF(Cleaned_Data!$N10>=3.5,"Excellent",IF(Cleaned_Data!$N10>=3,"Good",IF(Cleaned_Data!$N10>=2,"Average",IF(Cleaned_Data!$N10>=1,"Below Average","Very Poor")))) -> Good
A11: 1010 | B11: 16 | C11: Female | D11: General | E11: Graduation | F11: 18 | G11: 0 | H11: No | I11: High support | J11: Yes | K11: No | L11: No | M11: No | N11: 4 | O11: 0 | P11: =IF(Cleaned_Data!$N11>=3.5,"Excellent",IF(Cleaned_Data!$N11>=3,"Good",IF(Cleaned_Data!$N11>=2,"Average",IF(Cleaned_Data!$N11>=1,"Below Average","Very Poor")))) -> Excellent
A12: 1011 | B12: 17 | C12: Male | D12: General | E12: Graduation | F12: 12 | G12: 11 | H12: No | I12: Low support | J12: No | K12: No | L12: No | M12: No | N12: 2 | O12: 3 | P12: =IF(Cleaned_Data!$N12>=3.5,"Excellent",IF(Cleaned_Data!$N12>=3,"Good",IF(Cleaned_Data!$N12>=2,"Average",IF(Cleaned_Data!$N12>=1,"Below Average","Very Poor")))) -> Average
A13: 1012 | B13: 17 | C13: Male | D13: General | E13: Graduation | F13: 8 | G13: 15 | H13: No | I13: Moderate support | J13: No | K13: No | L13: No | M13: Yes | N13: 2 | O13: 4 | P13: =IF(Cleaned_Data!$N13>=3.5,"Excellent",IF(Cleaned_Data!$N13>=3,"Good",IF(Cleaned_Data!$N13>=2,"Average",IF(Cleaned_Data!$N13>=1,"Below Average","Very Poor")))) -> Average
... A2393: 3392 | B2393: 16 | C2393: Female | D2393: General | E2393: Post Graduation | F2393: 18 | G2393: 13 | H2393: No | I2393: Moderate support | J2393: No | K2393: No | L2393: No | M2393: Yes | N2393: 2 | O2393: 1 | P2393: =IF(Cleaned_Data!$N2393>=3.5,"Excellent",IF(Cleaned_Data!$N2393>=3,"Good",IF(Cleaned_Data!$N2393>=2,"Average",IF(Cleaned_Data!$N2393>=1,"Below Average","Very Poor")))) -> Average

Sheet Bar Chart
A3: Count of StudentID | B3: Column Labels
A4: Row Labels | B4: Female | C4: Male | D4: Grand Total
A5: Average | B5: 430 | C5: 408 | D5: 838
A6: Below Average | B6: 362 | C6: 344 | D6: 706
A7: Excellent | B7: 41 | C7: 36 | D7: 77
A8: Good | B8: 313 | C8: 316 | D8: 629
A9: Very Poor | B9: 76 | C9: 66 | D9: 142
A10: Grand Total | B10: 1222 | C10: 1170 | D10: 2392

Sheet Categorywise GPA
A3: Row Labels | B3: Average of GPA
A4: General | B4: 1.8898094
A5: OBC | B5: 1.954955
A6: SC | B6: 1.9212766
A7: ST | B7: 1.9452333
A8: Grand Total | B8: 1.9134615

Sheet StudyTime vs GPA
P2: Row Labels | Q2: Count of StudentID
A3: Row Labels | B3: Average of GPA | P3: No | Q3: 1671
A4: 0 | B4: 1.3538462 | P4: Yes | Q4: 721
A5: 1 | B5: 1.7168142 | P5: Grand Total | Q5: 2392
A6: 2 | B6: 1.7768595
A7: 3 | B7: 1.7603306
A8: 4 | B8: 1.7603306
A9: 5 | B9: 1.71875
A10: 6 | B10: 1.8547009
A11: 7 | B11: 1.7521368
A12: 8 | B12: 1.8550725
A13: 9 | B13: 1.9166667
A14: 10 | B14: 1.9496403
A15: 11 | B15: 2.0080645
A16: 12 | B16: 1.952381
A17: 13 | B17: 2.059322
... A24: 20 | B24: 2.1666667
A25: Grand Total | B25: 1.9134615

Sheet Dashboard
A1: 🎓 Student Performance Dashboard
B3: Total Students | D3: Total Male | F3: Total Female | H3: Average GPA
B4: =COUNT(Cleaned_Data!A2:A2393) -> 2392 | D4: =COUNTIF(Cleaned_Data!C2:C2393,"Male") -> 1170 | F4: =COUNTIF(Cleaned_Data!C2:C2393,"Female") -> 1222 | H4: =AVERAGE(Cleaned_Data!N2:N2393) -> 1.9134615
